<sdf version='1.6'>
  <world name='default'>
    <light name='sun' type='directional'>
      <cast_shadows>1</cast_shadows>
      <pose frame=''>0 0 10 0 -0 0</pose>
      <diffuse>0.8 0.8 0.8 1</diffuse>
      <specular>0.2 0.2 0.2 1</specular>
      <attenuation>
        <range>1000</range>
        <constant>0.9</constant>
        <linear>0.01</linear>
        <quadratic>0.001</quadratic>
      </attenuation>
      <direction>-0.5 0.1 -0.9</direction>
    </light>
    <model name='ground_plane'>
      <static>1</static>
      <link name='link'>
        <collision name='collision'>
          <geometry>
            <plane>
              <normal>0 0 1</normal>
              <size>100 100</size>
            </plane>
          </geometry>
          <surface>
            <friction>
              <ode>
                <mu>100</mu>
                <mu2>50</mu2>
              </ode>
              <torsional>
                <ode/>
              </torsional>
            </friction>
            <contact>
              <ode/>
            </contact>
            <bounce/>
          </surface>
          <max_contacts>10</max_contacts>
        </collision>
        <visual name='visual'>
          <cast_shadows>0</cast_shadows>
          <geometry>
            <plane>
              <normal>0 0 1</normal>
              <size>10000 10000</size>
            </plane>
          </geometry>
          <material>
            <script>
              <uri>model://grass_background/materials/scripts</uri>
              <uri>model://grass_background/materials/textures</uri>
              <name>GrassBackground</name>
            </script>
          </material>
        </visual>
        <self_collide>0</self_collide>
        <kinematic>0</kinematic>
        <enable_wind>0</enable_wind>
      </link>
    </model>
    <gravity>0 0 -9.8</gravity>
    <magnetic_field>6e-06 2.3e-05 -4.2e-05</magnetic_field>
    <atmosphere type='adiabatic'/>
    <physics name='default_physics' default='0' type='ode'>
      <max_step_size>0.001</max_step_size>
      <real_time_factor>1</real_time_factor>
      <real_time_update_rate>1000</real_time_update_rate>
    </physics>
    <scene>
      <ambient>0.4 0.4 0.4 1</ambient>
      <background>0.7 0.7 0.7 1</background>
      <shadows>1</shadows>
      <grid>0</grid>
    </scene>
    <spherical_coordinates>
      <surface_model>EARTH_WGS84</surface_model>
      <latitude_deg>0</latitude_deg>
      <longitude_deg>0</longitude_deg>
      <elevation>0</elevation>
      <heading_deg>0</heading_deg>
    </spherical_coordinates>
    <state world_name='default'>
      <sim_time>986 260000000</sim_time>
      <real_time>39 950778262</real_time>
      <wall_time>1648649264 328551399</wall_time>
      <iterations>39840</iterations>
      <model name='Curved Road - 50m_4_clone'>
        <pose frame=''>-227.97 351.484 0 0 -0 3.14159</pose>
        <scale>1 1 1</scale>
        <link name='link'>
          <pose frame=''>-227.97 351.484 0 0 -0 3.14159</pose>
          <velocity>0 0 0 0 -0 0</velocity>
          <acceleration>0 0 0 0 -0 0</acceleration>
          <wrench>0 0 0 0 -0 0</wrench>
        </link>
      </model>
      <model name='Curved Road - 50m_4_clone_clone'>
        <pose frame=''>-72.8675 196.761 0 0 0 -0.009167</pose>
        <scale>1 1 1</scale>
        <link name='link'>
          <pose frame=''>-72.8675 196.761 0 0 -0 -0.009167</pose>
          <velocity>0 0 0 0 -0 0</velocity>
          <acceleration>0 0 0 0 -0 0</acceleration>
          <wrench>0 0 0 0 -0 0</wrench>
        </link>
      </model>
      <model name='Curved Road - 50m_5_clone'>
        <pose frame=''>-227.831 296.058 0 0 0 -1.5707</pose>
        <scale>1 1 1</scale>
        <link name='link'>
          <pose frame=''>-227.831 296.058 0 0 0 -1.5707</pose>
          <velocity>0 0 0 0 -0 0</velocity>
          <acceleration>0 0 0 0 -0 0</acceleration>
          <wrench>0 0 0 0 -0 0</wrench>
        </link>
      </model>
      <model name='Curved Road - 50m_5_clone_clone'>
        <pose frame=''>-128.543 197.028 0 0 0 -1.5707</pose>
        <scale>1 1 1</scale>
        <link name='link'>
          <pose frame=''>-128.543 197.028 0 0 0 -1.5707</pose>
          <velocity>0 0 0 0 -0 0</velocity>
          <acceleration>0 0 0 0 -0 0</acceleration>
          <wrench>0 0 0 0 -0 0</wrench>
        </link>
      </model>
      <model name='Curved Road - 50m_6_clone'>
        <pose frame=''>-172.763 351.503 0 0 -0 1.5707</pose>
        <scale>1 1 1</scale>
        <link name='link'>
          <pose frame=''>-172.763 351.503 0 0 -0 1.5707</pose>
          <velocity>0 0 0 0 -0 0</velocity>
          <acceleration>0 0 0 0 -0 0</acceleration>
          <wrench>0 0 0 0 -0 0</wrench>
        </link>
      </model>
      <model name='Curved Road - 50m_6_clone_clone'>
        <pose frame=''>-72.6233 252.022 0 0 -0 1.5707</pose>
        <scale>1 1 1</scale>
        <link name='link'>
          <pose frame=''>-72.6233 252.022 0 0 -0 1.5707</pose>
          <velocity>0 0 0 0 -0 0</velocity>
          <acceleration>0 0 0 0 -0 0</acceleration>
          <wrench>0 0 0 0 -0 0</wrench>
        </link>
      </model>
      <model name='Intersection_15'>
        <pose frame=''>-150.742 273.966 0.010245 0 -0 0</pose>
        <scale>1 1 1</scale>
        <link name='link'>
          <pose frame=''>-150.742 273.966 0.010245 0 -0 0</pose>
          <velocity>0 0 0 0 -0 0</velocity>
          <acceleration>0 0 0 0 -0 0</acceleration>
          <wrench>0 0 0 0 -0 0</wrench>
        </link>
      </model>
      <model name='Straight Road - 50m_0'>
        <pose frame=''>-125.33 264.098 0 0 -0 3.14159</pose>
        <scale>1 1 1</scale>
        <link name='link'>
          <pose frame=''>-125.33 264.098 0 0 -0 3.14159</pose>
          <velocity>0 0 0 0 -0 0</velocity>
          <acceleration>0 0 0 0 -0 0</acceleration>
          <wrench>0 0 0 0 -0 0</wrench>
        </link>
      </model>
      <model name='Straight Road - 50m_8_clone'>
        <pose frame=''>-160.786 249.711 0 0 -0 1.5707</pose>
        <scale>1 1 1</scale>
        <link name='link'>
          <pose frame=''>-160.786 249.711 0 0 -0 1.5707</pose>
          <velocity>0 0 0 0 -0 0</velocity>
          <acceleration>0 0 0 0 -0 0</acceleration>
          <wrench>0 0 0 0 -0 0</wrench>
        </link>
      </model>
      <model name='Straight Road - 50m_8_clone_0'>
        <pose frame=''>-160.69 298.739 0 0 -0 1.5707</pose>
        <scale>1 1 1</scale>
        <link name='link'>
          <pose frame=''>-160.69 298.739 0 0 -0 1.5707</pose>
          <velocity>0 0 0 0 -0 0</velocity>
          <acceleration>0 0 0 0 -0 0</acceleration>
          <wrench>0 0 0 0 -0 0</wrench>
        </link>
      </model>
      <model name='Straight Road - 50m_9'>
        <pose frame=''>-175.153 284.011 0 0 -0 0</pose>
        <scale>1 1 1</scale>
        <link name='link'>
          <pose frame=''>-175.153 284.011 0 0 -0 0</pose>
          <velocity>0 0 0 0 -0 0</velocity>
          <acceleration>0 0 0 0 -0 0</acceleration>
          <wrench>0 0 0 0 -0 0</wrench>
        </link>
      </model>
      <model name='audibot'>
        <pose frame=''>-153.651 274.616 0.110235 0 -3e-06 -1.06103</pose>
        <scale>1 1 1</scale>
        <link name='base_footprint'>
          <pose frame=''>-153.651 274.616 0.110235 0 -3e-06 -1.06103</pose>
          <velocity>0.000721 -0.000955 -0.009715 -0.003259 -0.001915 -8.2e-05</velocity>
          <acceleration>0.056151 -0.108738 -5.95132 -0.868616 -1.53227 0.014261</acceleration>
          <wrench>91.0202 -176.264 -9647.1 0 -0 0</wrench>
        </link>
        <link name='steer_fl'>
          <pose frame=''>-151.642 272.7 0.470245 1e-06 -3e-06 -1.06103</pose>
          <velocity>-6.6e-05 8.4e-05 1.9e-05 -0.003305 -0.001713 -0.000286</velocity>
          <acceleration>0.060558 -0.066322 -0.233502 -1.19726 -0.884004 2.62803</acceleration>
          <wrench>1.21116 -1.32644 -4.67004 0 -0 0</wrench>
        </link>
        <link name='steer_fr'>
          <pose frame=''>-153.072 271.901 0.470245 2e-06 -3e-06 -1.06103</pose>
          <velocity>-0.000174 0.000186 7.4e-05 -0.003158 -0.002053 0.000207</velocity>
          <acceleration>0.174154 -0.088496 0.301593 -1.13444 -1.55282 -2.55423</acceleration>
          <wrench>3.48307 -1.76991 6.03185 0 -0 0</wrench>
        </link>
        <link name='wheel_fl'>
          <pose frame=''>-151.642 272.7 0.470245 1.5708 0.770918 2.08057</pose>
          <velocity>-3.2e-05 8.5e-05 -5.1e-05 -0.000135 -5.3e-05 -0.000328</velocity>
          <acceleration>-0.014108 -0.129029 -0.062296 3.08462 -0.078123 2.28401</acceleration>
          <wrench>-0.564313 -5.16116 -2.49183 0 -0 0</wrench>
        </link>
        <link name='wheel_fr'>
          <pose frame=''>-153.072 271.901 0.470246 -1.57079 -0.601953 -1.06104</pose>
          <velocity>-0.000193 0.000183 3.3e-05 -0.000461 -0.000509 0.000194</velocity>
          <acceleration>0.109159 -0.097486 0.024123 2.96024 -0.383388 -2.13749</acceleration>
          <wrench>4.36637 -3.89945 0.964938 0 -0 0</wrench>
        </link>
        <link name='wheel_rl'>
          <pose frame=''>-152.953 275.006 0.470235 1.5708 0.504829 2.08056</pose>
          <velocity>0.000107 0.000184 -0.009895 0.013874 0.006796 -6.6e-05</velocity>
          <acceleration>0.23405 -0.01746 -14.3614 1.86503 0.865778 -0.07291</acceleration>
          <wrench>9.362 -0.698401 -574.458 0 -0 0</wrench>
        </link>
        <link name='wheel_rr'>
          <pose frame=''>-154.35 274.225 0.470236 1.57078 1.43837 2.08055</pose>
          <velocity>-0.000147 0.000217 -0.009937 0.012677 0.00772 -0.000119</velocity>
          <acceleration>0.253371 -0.046589 -10.3449 -2.23749 0.556985 -2.97875</acceleration>
          <wrench>10.1348 -1.86356 -413.794 0 -0 0</wrench>
        </link>
      </model>
      <model name='ground_plane'>
        <pose frame=''>0 0 0 0 -0 0</pose>
        <scale>1 1 1</scale>
        <link name='link'>
          <pose frame=''>0 0 0 0 -0 0</pose>
          <velocity>0 0 0 0 -0 0</velocity>
          <acceleration>0 0 0 0 -0 0</acceleration>
          <wrench>0 0 0 0 -0 0</wrench>
        </link>
      </model>
      <light name='sun'>
        <pose frame=''>0 0 10 0 -0 0</pose>
      </light>
    </state>
    <gui fullscreen='0'>
      <camera name='user_camera'>
        <pose frame=''>-302.741 130.958 110.612 0 0.501798 0.758302</pose>
        <view_controller>orbit</view_controller>
        <projection_type>perspective</projection_type>
      </camera>
    </gui>
    <model name='Straight Road - 50m_0'>
      <static>1</static>
      <link name='link'>
        <inertial>
          <pose frame=''>0 0 0 0 -0 0</pose>
          <mass>1</mass>
          <inertia>
            <ixx>1</ixx>
            <iyy>1</iyy>
            <izz>1</izz>
            <ixy>0</ixy>
            <ixz>0</ixz>
            <iyz>0</iyz>
          </inertia>
        </inertial>
        <collision name='collision'>
          <geometry>
            <mesh>
              <uri>model://straight_road_50m/meshes/straight_road_50m.dae</uri>
              <scale>1 1 1</scale>
            </mesh>
          </geometry>
          <max_contacts>10</max_contacts>
          <surface>
            <contact>
              <ode/>
            </contact>
            <bounce/>
            <friction>
              <torsional>
                <ode/>
              </torsional>
              <ode/>
            </friction>
          </surface>
        </collision>
        <visual name='visual'>
          <geometry>
            <mesh>
              <uri>model://straight_road_50m/meshes/straight_road_50m.dae</uri>
              <scale>1 1 1</scale>
            </mesh>
          </geometry>
        </visual>
        <self_collide>0</self_collide>
        <kinematic>0</kinematic>
        <gravity>1</gravity>
        <enable_wind>0</enable_wind>
      </link>
      <pose frame=''>-5.03554 7.3342 0 0 -0 0</pose>
    </model>
    <model name='Intersection_15'>
      <static>1</static>
      <link name='link'>
        <inertial>
          <pose frame=''>0 0 0 0 -0 0</pose>
          <mass>1</mass>
          <inertia>
            <ixx>1</ixx>
            <iyy>1</iyy>
            <izz>1</izz>
            <ixy>0</ixy>
            <ixz>0</ixz>
            <iyz>0</iyz>
          </inertia>
        </inertial>
        <collision name='collision'>
          <geometry>
            <mesh>
              <uri>model://intersection/meshes/intersection.dae</uri>
              <scale>1 1 1</scale>
            </mesh>
          </geometry>
          <max_contacts>10</max_contacts>
          <surface>
            <contact>
              <ode/>
            </contact>
            <bounce/>
            <friction>
              <torsional>
                <ode/>
              </torsional>
              <ode/>
            </friction>
          </surface>
        </collision>
        <visual name='visual'>
          <geometry>
            <mesh>
              <uri>model://intersection/meshes/intersection.dae</uri>
              <scale>1 1 1</scale>
            </mesh>
          </geometry>
        </visual>
        <self_collide>0</self_collide>
        <kinematic>0</kinematic>
        <gravity>1</gravity>
        <enable_wind>0</enable_wind>
      </link>
      <pose frame=''>-135.621 274.654 0 0 -0 0</pose>
    </model>
    <model name='Straight Road - 50m_9'>
      <static>1</static>
      <link name='link'>
        <inertial>
          <pose frame=''>0 0 0 0 -0 0</pose>
          <mass>1</mass>
          <inertia>
            <ixx>1</ixx>
            <iyy>1</iyy>
            <izz>1</izz>
            <ixy>0</ixy>
            <ixz>0</ixz>
            <iyz>0</iyz>
          </inertia>
        </inertial>
        <collision name='collision'>
          <geometry>
            <mesh>
              <uri>model://straight_road_50m/meshes/straight_road_50m.dae</uri>
              <scale>1 1 1</scale>
            </mesh>
          </geometry>
          <max_contacts>10</max_contacts>
          <surface>
            <contact>
              <ode/>
            </contact>
            <bounce/>
            <friction>
              <torsional>
                <ode/>
              </torsional>
              <ode/>
            </friction>
          </surface>
        </collision>
        <visual name='visual'>
          <geometry>
            <mesh>
              <uri>model://straight_road_50m/meshes/straight_road_50m.dae</uri>
              <scale>1 1 1</scale>
            </mesh>
          </geometry>
        </visual>
        <self_collide>0</self_collide>
        <kinematic>0</kinematic>
        <gravity>1</gravity>
        <enable_wind>0</enable_wind>
      </link>
      <pose frame=''>-183.163 284.388 0 0 -0 0</pose>
    </model>
    <audio>
      <device>default</device>
    </audio>
    <wind/>
    <model name='audibot'>
      <link name='base_footprint'>
        <pose frame=''>0 0 0 0 -0 0</pose>
        <inertial>
          <pose frame=''>1.3258 0 0.36058 0 -0 0</pose>
          <mass>1621</mass>
          <inertia>
            <ixx>395.12</ixx>
            <ixy>0</ixy>
            <ixz>0.306251</ixz>
            <iyy>1658.33</iyy>
            <iyz>0</iyz>
            <izz>1954.47</izz>
          </inertia>
        </inertial>
        <collision name='base_footprint_fixed_joint_lump__base_link_collision'>
          <pose frame=''>1.361 0 0.385 0 -0 0</pose>
          <geometry>
            <mesh>
              <scale>1 1 1</scale>
              <uri>/opt/ros/melodic/share/audibot_description/meshes/body_collision.stl</uri>
            </mesh>
          </geometry>
          <surface>
            <contact>
              <ode/>
            </contact>
            <friction>
              <ode>
                <mu>0.5</mu>
                <mu2>0.5</mu2>
              </ode>
              <torsional>
                <ode/>
              </torsional>
            </friction>
            <bounce/>
          </surface>
          <max_contacts>10</max_contacts>
        </collision>
        <collision name='base_footprint_fixed_joint_lump__gps_collision_1'>
          <pose frame=''>1 0 1.3 0 -0 0</pose>
          <geometry>
            <cylinder>
              <length>0.05</length>
              <radius>0.1</radius>
            </cylinder>
          </geometry>
          <max_contacts>10</max_contacts>
          <surface>
            <contact>
              <ode/>
            </contact>
            <bounce/>
            <friction>
              <torsional>
                <ode/>
              </torsional>
              <ode/>
            </friction>
          </surface>
        </collision>
        <visual name='base_footprint_fixed_joint_lump__base_link_visual'>
          <pose frame=''>1.361 0 0.385 0 -0 0</pose>
          <geometry>
            <mesh>
              <scale>1 1 1</scale>
              <uri>/opt/ros/melodic/share/audibot_description/meshes/orange_body.dae</uri>
            </mesh>
          </geometry>
          <material>
            <script>
              <uri>__default__</uri>
              <name>__default__</name>
            </script>
          </material>
        </visual>
        <visual name='base_footprint_fixed_joint_lump__front_camera_visual_1'>
          <pose frame=''>2.1 0 1.15 -1.9708 -0 -1.5708</pose>
          <geometry>
            <box>
              <size>0.1 0.1 0.1</size>
            </box>
          </geometry>
        </visual>
        <visual name='base_footprint_fixed_joint_lump__gps_visual_2'>
          <pose frame=''>1 0 1.3 0 -0 0</pose>
          <geometry>
            <cylinder>
              <length>0.05</length>
              <radius>0.1</radius>
            </cylinder>
          </geometry>
        </visual>
        <velocity_decay/>
        <gravity>1</gravity>
        <velocity_decay/>
        <sensor name='front_camera_camera' type='camera'>
          <update_rate>30</update_rate>
          <camera name='cam'>
            <horizontal_fov>1.39626</horizontal_fov>
            <image>
              <width>800</width>
              <height>800</height>
              <format>R8G8B8</format>
            </image>
            <clip>
              <near>0.02</near>
              <far>300</far>
            </clip>
            <noise>
              <type>gaussian</type>
              <mean>0</mean>
              <stddev>0.007</stddev>
            </noise>
          </camera>
          <plugin name='camera_controller' filename='libgazebo_ros_camera.so'>
            <alwaysOn>1</alwaysOn>
            <updateRate>0.0</updateRate>
            <cameraName>front_camera</cameraName>
            <imageTopicName>image_raw</imageTopicName>
            <cameraInfoTopicName>camera_info</cameraInfoTopicName>
            <frameName>front_camera</frameName>
            <hackBaseline>0.0</hackBaseline>
            <distortionK1>0.0</distortionK1>
            <distortionK2>0.0</distortionK2>
            <distortionK3>0.0</distortionK3>
            <distortionT1>0.0</distortionT1>
            <distortionT2>0.0</distortionT2>
            <robotNamespace>/audibot/</robotNamespace>
          </plugin>
          <pose frame=''>2.1 0 1.15 0 0.4 0</pose>
        </sensor>
        <self_collide>0</self_collide>
        <enable_wind>0</enable_wind>
        <kinematic>0</kinematic>
      </link>
      <link name='steer_fl'>
        <pose frame=''>2.652 0.819 0.36 0 -0 0</pose>
        <inertial>
          <pose frame=''>-0.013054 -0.0295 0 0 -0 0</pose>
          <mass>20</mass>
          <inertia>
            <ixx>2</ixx>
            <ixy>0</ixy>
            <ixz>0</ixz>
            <iyy>2</iyy>
            <iyz>0</iyz>
            <izz>2</izz>
          </inertia>
        </inertial>
        <self_collide>0</self_collide>
        <enable_wind>0</enable_wind>
        <kinematic>0</kinematic>
      </link>
      <joint name='steer_fl' type='revolute'>
        <child>steer_fl</child>
        <parent>base_footprint</parent>
        <axis>
          <xyz>0 0 1</xyz>
          <limit>
            <lower>-0.6</lower>
            <upper>0.6</upper>
            <effort>0</effort>
            <velocity>0</velocity>
          </limit>
          <dynamics>
            <spring_reference>0</spring_reference>
            <spring_stiffness>0</spring_stiffness>
          </dynamics>
          <use_parent_model_frame>1</use_parent_model_frame>
        </axis>
      </joint>
      <link name='wheel_fl'>
        <pose frame=''>2.652 0.819 0.36 -1.5708 0 0</pose>
        <inertial>
          <pose frame=''>0 0 0 0 -0 0</pose>
          <mass>40</mass>
          <inertia>
            <ixx>1.50433</ixx>
            <ixy>0</ixy>
            <ixz>0</ixz>
            <iyy>1.50433</iyy>
            <iyz>0</iyz>
            <izz>2.592</izz>
          </inertia>
        </inertial>
        <collision name='wheel_fl_collision'>
          <pose frame=''>0 0 0 0 -0 0</pose>
          <geometry>
            <cylinder>
              <length>0.25</length>
              <radius>0.36</radius>
            </cylinder>
          </geometry>
          <surface>
            <contact>
              <ode/>
            </contact>
            <friction>
              <ode>
                <mu>1.75</mu>
                <mu2>1.75</mu2>
              </ode>
              <torsional>
                <ode/>
              </torsional>
            </friction>
            <bounce/>
          </surface>
          <max_contacts>10</max_contacts>
        </collision>
        <visual name='wheel_fl_visual'>
          <pose frame=''>0 0 0 -1.5708 -0 -3.14159</pose>
          <geometry>
            <mesh>
              <scale>1 1 1</scale>
              <uri>/opt/ros/melodic/share/audibot_description/meshes/wheel.dae</uri>
            </mesh>
          </geometry>
          <material>
            <script>
              <uri>__default__</uri>
              <name>__default__</name>
            </script>
          </material>
        </visual>
        <gravity>1</gravity>
        <velocity_decay/>
        <self_collide>0</self_collide>
        <enable_wind>0</enable_wind>
        <kinematic>0</kinematic>
      </link>
      <joint name='wheel_fl' type='revolute'>
        <child>wheel_fl</child>
        <parent>steer_fl</parent>
        <axis>
          <xyz>0 1 0</xyz>
          <limit>
            <lower>-1e+16</lower>
            <upper>1e+16</upper>
          </limit>
          <dynamics>
            <spring_reference>0</spring_reference>
            <spring_stiffness>0</spring_stiffness>
          </dynamics>
          <use_parent_model_frame>1</use_parent_model_frame>
        </axis>
        <physics>
          <ode>
            <limit>
              <cfm>0</cfm>
              <erp>0.2</erp>
            </limit>
          </ode>
        </physics>
      </joint>
      <link name='steer_fr'>
        <pose frame=''>2.652 -0.819 0.36 0 -0 0</pose>
        <inertial>
          <pose frame=''>-0.013054 -0.0295 0 0 -0 0</pose>
          <mass>20</mass>
          <inertia>
            <ixx>2</ixx>
            <ixy>0</ixy>
            <ixz>0</ixz>
            <iyy>2</iyy>
            <iyz>0</iyz>
            <izz>2</izz>
          </inertia>
        </inertial>
        <self_collide>0</self_collide>
        <enable_wind>0</enable_wind>
        <kinematic>0</kinematic>
      </link>
      <joint name='steer_fr' type='revolute'>
        <child>steer_fr</child>
        <parent>base_footprint</parent>
        <axis>
          <xyz>0 0 1</xyz>
          <limit>
            <lower>-0.6</lower>
            <upper>0.6</upper>
            <effort>0</effort>
            <velocity>0</velocity>
          </limit>
          <dynamics>
            <spring_reference>0</spring_reference>
            <spring_stiffness>0</spring_stiffness>
          </dynamics>
          <use_parent_model_frame>1</use_parent_model_frame>
        </axis>
      </joint>
      <link name='wheel_fr'>
        <pose frame=''>2.652 -0.819 0.36 -1.5708 0 0</pose>
        <inertial>
          <pose frame=''>0 0 0 0 -0 0</pose>
          <mass>40</mass>
          <inertia>
            <ixx>1.50433</ixx>
            <ixy>0</ixy>
            <ixz>0</ixz>
            <iyy>1.50433</iyy>
            <iyz>0</iyz>
            <izz>2.592</izz>
          </inertia>
        </inertial>
        <collision name='wheel_fr_collision'>
          <pose frame=''>0 0 0 0 -0 0</pose>
          <geometry>
            <cylinder>
              <length>0.25</length>
              <radius>0.36</radius>
            </cylinder>
          </geometry>
          <surface>
            <contact>
              <ode/>
            </contact>
            <friction>
              <ode>
                <mu>1.75</mu>
                <mu2>1.75</mu2>
              </ode>
              <torsional>
                <ode/>
              </torsional>
            </friction>
            <bounce/>
          </surface>
          <max_contacts>10</max_contacts>
        </collision>
        <visual name='wheel_fr_visual'>
          <pose frame=''>0 0 0 1.5708 -0 0</pose>
          <geometry>
            <mesh>
              <scale>1 1 1</scale>
              <uri>/opt/ros/melodic/share/audibot_description/meshes/wheel.dae</uri>
            </mesh>
          </geometry>
          <material>
            <script>
              <uri>__default__</uri>
              <name>__default__</name>
            </script>
          </material>
        </visual>
        <gravity>1</gravity>
        <velocity_decay/>
        <self_collide>0</self_collide>
        <enable_wind>0</enable_wind>
        <kinematic>0</kinematic>
      </link>
      <joint name='wheel_fr' type='revolute'>
        <child>wheel_fr</child>
        <parent>steer_fr</parent>
        <axis>
          <xyz>0 1 0</xyz>
          <limit>
            <lower>-1e+16</lower>
            <upper>1e+16</upper>
          </limit>
          <dynamics>
            <spring_reference>0</spring_reference>
            <spring_stiffness>0</spring_stiffness>
          </dynamics>
          <use_parent_model_frame>1</use_parent_model_frame>
        </axis>
        <physics>
          <ode>
            <limit>
              <cfm>0</cfm>
              <erp>0.2</erp>
            </limit>
          </ode>
        </physics>
      </joint>
      <link name='wheel_rl'>
        <pose frame=''>0 0.8 0.36 -1.5708 0 0</pose>
        <inertial>
          <pose frame=''>0 0 0 0 -0 0</pose>
          <mass>40</mass>
          <inertia>
            <ixx>1.50433</ixx>
            <ixy>0</ixy>
            <ixz>0</ixz>
            <iyy>1.50433</iyy>
            <iyz>0</iyz>
            <izz>2.592</izz>
          </inertia>
        </inertial>
        <collision name='wheel_rl_collision'>
          <pose frame=''>0 0 0 0 -0 0</pose>
          <geometry>
            <cylinder>
              <length>0.25</length>
              <radius>0.36</radius>
            </cylinder>
          </geometry>
          <surface>
            <contact>
              <ode/>
            </contact>
            <friction>
              <ode>
                <mu>1.75</mu>
                <mu2>1.75</mu2>
              </ode>
              <torsional>
                <ode/>
              </torsional>
            </friction>
            <bounce/>
          </surface>
          <max_contacts>10</max_contacts>
        </collision>
        <visual name='wheel_rl_visual'>
          <pose frame=''>0 0 0 -1.5708 -0 3.14159</pose>
          <geometry>
            <mesh>
              <scale>1 1 1</scale>
              <uri>/opt/ros/melodic/share/audibot_description/meshes/wheel.dae</uri>
            </mesh>
          </geometry>
          <material>
            <script>
              <uri>__default__</uri>
              <name>__default__</name>
            </script>
          </material>
        </visual>
        <gravity>1</gravity>
        <velocity_decay/>
        <self_collide>0</self_collide>
        <enable_wind>0</enable_wind>
        <kinematic>0</kinematic>
      </link>
      <joint name='wheel_rl' type='revolute'>
        <child>wheel_rl</child>
        <parent>base_footprint</parent>
        <axis>
          <xyz>0 1 0</xyz>
          <limit>
            <lower>-1e+16</lower>
            <upper>1e+16</upper>
          </limit>
          <dynamics>
            <spring_reference>0</spring_reference>
            <spring_stiffness>0</spring_stiffness>
          </dynamics>
          <use_parent_model_frame>1</use_parent_model_frame>
        </axis>
        <physics>
          <ode>
            <limit>
              <cfm>0</cfm>
              <erp>0.2</erp>
            </limit>
          </ode>
        </physics>
      </joint>
      <link name='wheel_rr'>
        <pose frame=''>0 -0.8 0.36 -1.5708 0 0</pose>
        <inertial>
          <pose frame=''>0 0 0 0 -0 0</pose>
          <mass>40</mass>
          <inertia>
            <ixx>1.50433</ixx>
            <ixy>0</ixy>
            <ixz>0</ixz>
            <iyy>1.50433</iyy>
            <iyz>0</iyz>
            <izz>2.592</izz>
          </inertia>
        </inertial>
        <collision name='wheel_rr_collision'>
          <pose frame=''>0 0 0 0 -0 0</pose>
          <geometry>
            <cylinder>
              <length>0.25</length>
              <radius>0.36</radius>
            </cylinder>
          </geometry>
          <surface>
            <contact>
              <ode/>
            </contact>
            <friction>
              <ode>
                <mu>1.75</mu>
                <mu2>1.75</mu2>
              </ode>
              <torsional>
                <ode/>
              </torsional>
            </friction>
            <bounce/>
          </surface>
          <max_contacts>10</max_contacts>
        </collision>
        <visual name='wheel_rr_visual'>
          <pose frame=''>0 0 0 1.5708 -0 0</pose>
          <geometry>
            <mesh>
              <scale>1 1 1</scale>
              <uri>/opt/ros/melodic/share/audibot_description/meshes/wheel.dae</uri>
            </mesh>
          </geometry>
          <material>
            <script>
              <uri>__default__</uri>
              <name>__default__</name>
            </script>
          </material>
        </visual>
        <gravity>1</gravity>
        <velocity_decay/>
        <self_collide>0</self_collide>
        <enable_wind>0</enable_wind>
        <kinematic>0</kinematic>
      </link>
      <joint name='wheel_rr' type='revolute'>
        <child>wheel_rr</child>
        <parent>base_footprint</parent>
        <axis>
          <xyz>0 1 0</xyz>
          <limit>
            <lower>-1e+16</lower>
            <upper>1e+16</upper>
          </limit>
          <dynamics>
            <spring_reference>0</spring_reference>
            <spring_stiffness>0</spring_stiffness>
          </dynamics>
          <use_parent_model_frame>1</use_parent_model_frame>
        </axis>
        <physics>
          <ode>
            <limit>
              <cfm>0</cfm>
              <erp>0.2</erp>
            </limit>
          </ode>
        </physics>
      </joint>
      <plugin name='audibot_interface_plugin' filename='libaudibot_interface_plugin.so'>
        <robotName>audibot</robotName>
        <pubTf>1</pubTf>
        <tfFreq>100.0</tfFreq>
        <robotNamespace>/audibot/</robotNamespace>
      </plugin>
      <plugin name='joint_state_publisher' filename='libgazebo_ros_joint_state_publisher.so'>
        <robotNamespace>audibot</robotNamespace>
        <jointName>steer_fl, steer_fr, wheel_fl, wheel_fr, wheel_rl, wheel_rr</jointName>
        <updateRate>100</updateRate>
        <alwaysOn>1</alwaysOn>
      </plugin>
      <static>0</static>
      <plugin name='gps_plugin' filename='libugv_course_gazebo_plugins_gps.so'>
        <link_name>gps</link_name>
        <ref_lat>42.0</ref_lat>
        <ref_lon>-83.0</ref_lon>
        <ant_offset_x>0.0</ant_offset_x>
        <ant_offset_y>0.0</ant_offset_y>
        <ant_offset_z>0.0</ant_offset_z>
        <update_rate>50.0</update_rate>
        <pub_heading>1</pub_heading>
        <robotNamespace>/audibot/</robotNamespace>
      </plugin>
      <pose frame=''>-152.5 275.2 0.3 0 0 -1.5707</pose>
    </model>
    <model name='Straight Road - 50m_8_clone'>
      <static>1</static>
      <link name='link'>
        <inertial>
          <pose frame=''>0 0 0 0 -0 0</pose>
          <mass>1</mass>
          <inertia>
            <ixx>1</ixx>
            <iyy>1</iyy>
            <izz>1</izz>
            <ixy>0</ixy>
            <ixz>0</ixz>
            <iyz>0</iyz>
          </inertia>
        </inertial>
        <collision name='collision'>
          <geometry>
            <mesh>
              <uri>model://straight_road_50m/meshes/straight_road_50m.dae</uri>
              <scale>1 1 1</scale>
            </mesh>
          </geometry>
          <max_contacts>10</max_contacts>
          <surface>
            <contact>
              <ode/>
            </contact>
            <bounce/>
            <friction>
              <torsional>
                <ode/>
              </torsional>
              <ode/>
            </friction>
          </surface>
        </collision>
        <visual name='visual'>
          <geometry>
            <mesh>
              <uri>model://straight_road_50m/meshes/straight_road_50m.dae</uri>
              <scale>1 1 1</scale>
            </mesh>
          </geometry>
        </visual>
        <self_collide>0</self_collide>
        <kinematic>0</kinematic>
        <gravity>1</gravity>
        <enable_wind>0</enable_wind>
      </link>
      <pose frame=''>-160.76 242.155 0 0 -0 1.5707</pose>
    </model>
    <model name='Straight Road - 50m_8_clone_0'>
      <static>1</static>
      <link name='link'>
        <inertial>
          <pose frame=''>0 0 0 0 -0 0</pose>
          <mass>1</mass>
          <inertia>
            <ixx>1</ixx>
            <iyy>1</iyy>
            <izz>1</izz>
            <ixy>0</ixy>
            <ixz>0</ixz>
            <iyz>0</iyz>
          </inertia>
        </inertial>
        <collision name='collision'>
          <geometry>
            <mesh>
              <uri>model://straight_road_50m/meshes/straight_road_50m.dae</uri>
              <scale>1 1 1</scale>
            </mesh>
          </geometry>
          <max_contacts>10</max_contacts>
          <surface>
            <contact>
              <ode/>
            </contact>
            <bounce/>
            <friction>
              <torsional>
                <ode/>
              </torsional>
              <ode/>
            </friction>
          </surface>
        </collision>
        <visual name='visual'>
          <geometry>
            <mesh>
              <uri>model://straight_road_50m/meshes/straight_road_50m.dae</uri>
              <scale>1 1 1</scale>
            </mesh>
          </geometry>
        </visual>
        <self_collide>0</self_collide>
        <kinematic>0</kinematic>
        <gravity>1</gravity>
        <enable_wind>0</enable_wind>
      </link>
      <pose frame=''>-160.741 307.164 0 0 -0 1.5707</pose>
    </model>
    <model name='Curved Road - 50m_6_clone'>
      <static>1</static>
      <link name='link'>
        <inertial>
          <pose frame=''>0 0 0 0 -0 0</pose>
          <mass>1</mass>
          <inertia>
            <ixx>1</ixx>
            <iyy>1</iyy>
            <izz>1</izz>
            <ixy>0</ixy>
            <ixz>0</ixz>
            <iyz>0</iyz>
          </inertia>
        </inertial>
        <collision name='collision'>
          <geometry>
            <mesh>
              <uri>model://curved_road_50m/meshes/curved_road_50m.dae</uri>
              <scale>1 1 1</scale>
            </mesh>
          </geometry>
          <max_contacts>10</max_contacts>
          <surface>
            <contact>
              <ode/>
            </contact>
            <bounce/>
            <friction>
              <torsional>
                <ode/>
              </torsional>
              <ode/>
            </friction>
          </surface>
        </collision>
        <visual name='visual'>
          <geometry>
            <mesh>
              <uri>model://curved_road_50m/meshes/curved_road_50m.dae</uri>
              <scale>1 1 1</scale>
            </mesh>
          </geometry>
        </visual>
        <self_collide>0</self_collide>
        <kinematic>0</kinematic>
        <gravity>1</gravity>
        <enable_wind>0</enable_wind>
      </link>
      <pose frame=''>-167.854 360.774 0 0 -0 1.5707</pose>
    </model>
    <model name='Curved Road - 50m_5_clone'>
      <static>1</static>
      <link name='link'>
        <inertial>
          <pose frame=''>0 0 0 0 -0 0</pose>
          <mass>1</mass>
          <inertia>
            <ixx>1</ixx>
            <iyy>1</iyy>
            <izz>1</izz>
            <ixy>0</ixy>
            <ixz>0</ixz>
            <iyz>0</iyz>
          </inertia>
        </inertial>
        <collision name='collision'>
          <geometry>
            <mesh>
              <uri>model://curved_road_50m/meshes/curved_road_50m.dae</uri>
              <scale>1 1 1</scale>
            </mesh>
          </geometry>
          <max_contacts>10</max_contacts>
          <surface>
            <contact>
              <ode/>
            </contact>
            <bounce/>
            <friction>
              <torsional>
                <ode/>
              </torsional>
              <ode/>
            </friction>
          </surface>
        </collision>
        <visual name='visual'>
          <geometry>
            <mesh>
              <uri>model://curved_road_50m/meshes/curved_road_50m.dae</uri>
              <scale>1 1 1</scale>
            </mesh>
          </geometry>
        </visual>
        <self_collide>0</self_collide>
        <kinematic>0</kinematic>
        <gravity>1</gravity>
        <enable_wind>0</enable_wind>
      </link>
      <pose frame=''>-238.039 290.732 0 0 0 -1.5707</pose>
    </model>
    <model name='Curved Road - 50m_4_clone'>
      <static>1</static>
      <link name='link'>
        <inertial>
          <pose frame=''>0 0 0 0 -0 0</pose>
          <mass>1</mass>
          <inertia>
            <ixx>1</ixx>
            <iyy>1</iyy>
            <izz>1</izz>
            <ixy>0</ixy>
            <ixz>0</ixz>
            <iyz>0</iyz>
          </inertia>
        </inertial>
        <collision name='collision'>
          <geometry>
            <mesh>
              <uri>model://curved_road_50m/meshes/curved_road_50m.dae</uri>
              <scale>1 1 1</scale>
            </mesh>
          </geometry>
          <max_contacts>10</max_contacts>
          <surface>
            <contact>
              <ode/>
            </contact>
            <bounce/>
            <friction>
              <torsional>
                <ode/>
              </torsional>
              <ode/>
            </friction>
          </surface>
        </collision>
        <visual name='visual'>
          <geometry>
            <mesh>
              <uri>model://curved_road_50m/meshes/curved_road_50m.dae</uri>
              <scale>1 1 1</scale>
            </mesh>
          </geometry>
        </visual>
        <self_collide>0</self_collide>
        <kinematic>0</kinematic>
        <gravity>1</gravity>
        <enable_wind>0</enable_wind>
      </link>
      <pose frame=''>-231.451 356.745 0 0 -0 3.14159</pose>
    </model>
    <model name='Curved Road - 50m_6_clone_clone'>
      <static>1</static>
      <link name='link'>
        <inertial>
          <pose frame=''>0 0 0 0 -0 0</pose>
          <mass>1</mass>
          <inertia>
            <ixx>1</ixx>
            <iyy>1</iyy>
            <izz>1</izz>
            <ixy>0</ixy>
            <ixz>0</ixz>
            <iyz>0</iyz>
          </inertia>
        </inertial>
        <collision name='collision'>
          <geometry>
            <mesh>
              <uri>model://curved_road_50m/meshes/curved_road_50m.dae</uri>
              <scale>1 1 1</scale>
            </mesh>
          </geometry>
          <max_contacts>10</max_contacts>
          <surface>
            <contact>
              <ode/>
            </contact>
            <bounce/>
            <friction>
              <torsional>
                <ode/>
              </torsional>
              <ode/>
            </friction>
          </surface>
        </collision>
        <visual name='visual'>
          <geometry>
            <mesh>
              <uri>model://curved_road_50m/meshes/curved_road_50m.dae</uri>
              <scale>1 1 1</scale>
            </mesh>
          </geometry>
        </visual>
        <self_collide>0</self_collide>
        <kinematic>0</kinematic>
        <gravity>1</gravity>
        <enable_wind>0</enable_wind>
      </link>
      <pose frame=''>-65.7471 252.359 0 0 -0 1.5707</pose>
    </model>
    <model name='Curved Road - 50m_5_clone_clone'>
      <static>1</static>
      <link name='link'>
        <inertial>
          <pose frame=''>0 0 0 0 -0 0</pose>
          <mass>1</mass>
          <inertia>
            <ixx>1</ixx>
            <iyy>1</iyy>
            <izz>1</izz>
            <ixy>0</ixy>
            <ixz>0</ixz>
            <iyz>0</iyz>
          </inertia>
        </inertial>
        <collision name='collision'>
          <geometry>
            <mesh>
              <uri>model://curved_road_50m/meshes/curved_road_50m.dae</uri>
              <scale>1 1 1</scale>
            </mesh>
          </geometry>
          <max_contacts>10</max_contacts>
          <surface>
            <contact>
              <ode/>
            </contact>
            <bounce/>
            <friction>
              <torsional>
                <ode/>
              </torsional>
              <ode/>
            </friction>
          </surface>
        </collision>
        <visual name='visual'>
          <geometry>
            <mesh>
              <uri>model://curved_road_50m/meshes/curved_road_50m.dae</uri>
              <scale>1 1 1</scale>
            </mesh>
          </geometry>
        </visual>
        <self_collide>0</self_collide>
        <kinematic>0</kinematic>
        <gravity>1</gravity>
        <enable_wind>0</enable_wind>
      </link>
      <pose frame=''>-128.558 189.438 0 0 0 -1.5707</pose>
    </model>
    <model name='Curved Road - 50m_4_clone_clone'>
      <static>1</static>
      <link name='link'>
        <inertial>
          <pose frame=''>0 0 0 0 -0 0</pose>
          <mass>1</mass>
          <inertia>
            <ixx>1</ixx>
            <iyy>1</iyy>
            <izz>1</izz>
            <ixy>0</ixy>
            <ixz>0</ixz>
            <iyz>0</iyz>
          </inertia>
        </inertial>
        <collision name='collision'>
          <geometry>
            <mesh>
              <uri>model://curved_road_50m/meshes/curved_road_50m.dae</uri>
              <scale>1 1 1</scale>
            </mesh>
          </geometry>
          <max_contacts>10</max_contacts>
          <surface>
            <contact>
              <ode/>
            </contact>
            <bounce/>
            <friction>
              <torsional>
                <ode/>
              </torsional>
              <ode/>
            </friction>
          </surface>
        </collision>
        <visual name='visual'>
          <geometry>
            <mesh>
              <uri>model://curved_road_50m/meshes/curved_road_50m.dae</uri>
              <scale>1 1 1</scale>
            </mesh>
          </geometry>
        </visual>
        <self_collide>0</self_collide>
        <kinematic>0</kinematic>
        <gravity>1</gravity>
        <enable_wind>0</enable_wind>
      </link>
      <pose frame=''>-67.4345 191.029 0 0 -0 3.14159</pose>
    </model>
  </world>
</sdf>
